Workbook

Sheet Hoja1
A1: CUI | B1: SNIP | C1: Último Estado | D1: Cant. Obs. Adm. | E1: Cant. Obs. Cal. | F1: Cant. Eval. Inv. | G1: Etapa | H1: Fecha Inicio | I1: Fecha Fin | J1: Diferencial Días | K1: Monto Inversión | L1: MONITOREO | M1: MONTO CONTRATADO OBRA | N1: MONTO CONTRATADO SUPERVISION | O1: MONTO LIQUIDACIÓN OBRA | P1: MONTO LIQUIDACIÓN SUPERVISIÓN | Q1: MONTO LIQUIDACIÓN COMPLEMENTARIO
A2: 2031691 | B2: 34548 | C2: Abandono | D2: 2 | E2: 1 | F2: 0 | G2: Calidad | H2: 44431.887 | I2: 44456.503 | J2: 25 | K2: 46971858 | L2: =+VLOOKUP(A2,Hoja2!$A$2:$X$2596,19,FALSE) -> En Ejecución | M2: =+VLOOKUP(A2,Hoja2!$A$2:$X$2596,15,FALSE) -> 37327357 | N2: =+VLOOKUP(A2,Hoja2!$A$2:$X$2596,17,FALSE) -> 1420721.6 | O2: =+VLOOKUP(A2,Hoja2!$A$2:$X$2596,22,FALSE) | P2: =+VLOOKUP(A2,Hoja2!$A$2:$X$2596,23,FALSE) | Q2: =+VLOOKUP(A2,Hoja2!$A$2:$X$2596,24,FALSE)
A3: 2031691 | B3: 34548 | C3: Desestimado | D3: 1 | E3: 4 | F3: 0 | G3: Calidad | H3: 44574.722 | I3: 44768.741 | J3: 194 | K3: 46971858 | L3: =+VLOOKUP(A3,Hoja2!$A$2:$X$2596,19,FALSE) -> En Ejecución | M3: =+VLOOKUP(A3,Hoja2!$A$2:$X$2596,15,FALSE) -> 37327357 | N3: =+VLOOKUP(A3,Hoja2!$A$2:$X$2596,17,FALSE) -> 1420721.6 | O3: =+VLOOKUP(A3,Hoja2!$A$2:$X$2596,22,FALSE) | P3: =+VLOOKUP(A3,Hoja2!$A$2:$X$2596,23,FALSE) | Q3: =+VLOOKUP(A3,Hoja2!$A$2:$X$2596,24,FALSE)
A4: 2031691 | B4: 34548 | C4: Aprobado | D4: 1 | E4: 8 | F4: 0 | G4: Calidad | H4: 44993.446 | I4: 45034.775 | J4: 41 | K4: 46971858 | L4: =+VLOOKUP(A4,Hoja2!$A$2:$X$2596,19,FALSE) -> En Ejecución | M4: =+VLOOKUP(A4,Hoja2!$A$2:$X$2596,15,FALSE) -> 37327357 | N4: =+VLOOKUP(A4,Hoja2!$A$2:$X$2596,17,FALSE) -> 1420721.6 | O4: =+VLOOKUP(A4,Hoja2!$A$2:$X$2596,22,FALSE) | P4: =+VLOOKUP(A4,Hoja2!$A$2:$X$2596,23,FALSE) | Q4: =+VLOOKUP(A4,Hoja2!$A$2:$X$2596,24,FALSE)
A5: 2071970 | B5: 78623 | C5: Aprobado | D5: 2 | E5: 3 | F5: 0 | G5: Calidad | H5: 44412.822 | I5: 44434.548 | J5: 22 | K5: 9296404 | L5: =+VLOOKUP(A5,Hoja2!$A$2:$X$2596,19,FALSE) -> En Ejecución | M5: =+VLOOKUP(A5,Hoja2!$A$2:$X$2596,15,FALSE) -> 29497031 | N5: =+VLOOKUP(A5,Hoja2!$A$2:$X$2596,17,FALSE) -> 1233859.6 | O5: =+VLOOKUP(A5,Hoja2!$A$2:$X$2596,22,FALSE) | P5: =+VLOOKUP(A5,Hoja2!$A$2:$X$2596,23,FALSE) | Q5: =+VLOOKUP(A5,Hoja2!$A$2:$X$2596,24,FALSE)
A6: 2082525 | B6: 80758 | C6: Abandono | D6: 2 | E6: 0 | F6: 0 | G6: Admisibilidad | H6: 44525.445 | I6: 44539.692 | J6: 14 | K6: 67763285 | L6: =+VLOOKUP(A6,Hoja2!$A$2:$X$2596,19,FALSE) -> #N/A | M6: =+VLOOKUP(A6,Hoja2!$A$2:$X$2596,15,FALSE) -> #N/A | N6: =+VLOOKUP(A6,Hoja2!$A$2:$X$2596,17,FALSE) -> #N/A | O6: =+VLOOKUP(A6,Hoja2!$A$2:$X$2596,22,FALSE) -> #N/A | P6: =+VLOOKUP(A6,Hoja2!$A$2:$X$2596,23,FALSE) -> #N/A | Q6: =+VLOOKUP(A6,Hoja2!$A$2:$X$2596,24,FALSE) -> #N/A
A7: 2082525 | B7: 80758 | C7: Desestimado | D7: 1 | E7: 2 | F7: 0 | G7: Calidad | H7: 44606.375 | I7: 44754.615 | J7: 148 | K7: 67763285 | L7: =+VLOOKUP(A7,Hoja2!$A$2:$X$2596,19,FALSE) -> #N/A | M7: =+VLOOKUP(A7,Hoja2!$A$2:$X$2596,15,FALSE) -> #N/A | N7: =+VLOOKUP(A7,Hoja2!$A$2:$X$2596,17,FALSE) -> #N/A | O7: =+VLOOKUP(A7,Hoja2!$A$2:$X$2596,22,FALSE) -> #N/A | P7: =+VLOOKUP(A7,Hoja2!$A$2:$X$2596,23,FALSE) -> #N/A | Q7: =+VLOOKUP(A7,Hoja2!$A$2:$X$2596,24,FALSE) -> #N/A
A8: 2082525 | B8: 80758 | C8: Desestimado | D8: 1 | E8: 4 | F8: 0 | G8: Calidad | H8: 44845.729 | I8: 45096.723 | J8: 251 | K8: 67763285 | L8: =+VLOOKUP(A8,Hoja2!$A$2:$X$2596,19,FALSE) -> #N/A | M8: =+VLOOKUP(A8,Hoja2!$A$2:$X$2596,15,FALSE) -> #N/A | N8: =+VLOOKUP(A8,Hoja2!$A$2:$X$2596,17,FALSE) -> #N/A | O8: =+VLOOKUP(A8,Hoja2!$A$2:$X$2596,22,FALSE) -> #N/A | P8: =+VLOOKUP(A8,Hoja2!$A$2:$X$2596,23,FALSE) -> #N/A | Q8: =+VLOOKUP(A8,Hoja2!$A$2:$X$2596,24,FALSE) -> #N/A
A9: 2082525 | B9: 80758 | C9: Desestimado | D9: 1 | E9: 1 | F9: 0 | G9: Calidad | H9: 45322.333 | I9: 45411.746 | J9: 89 | K9: 67763285 | L9: =+VLOOKUP(A9,Hoja2!$A$2:$X$2596,19,FALSE) -> #N/A | M9: =+VLOOKUP(A9,Hoja2!$A$2:$X$2596,15,FALSE) -> #N/A | N9: =+VLOOKUP(A9,Hoja2!$A$2:$X$2596,17,FALSE) -> #N/A | O9: =+VLOOKUP(A9,Hoja2!$A$2:$X$2596,22,FALSE) -> #N/A | P9: =+VLOOKUP(A9,Hoja2!$A$2:$X$2596,23,FALSE) -> #N/A | Q9: =+VLOOKUP(A9,Hoja2!$A$2:$X$2596,24,FALSE) -> #N/A
A10: 2082525 | B10: 80758 | C10: Desestimado | D10: 5 | E10: 0 | F10: 0 | G10: Admisibilidad | H10: 45645.713 | I10: 45768.716 | J10: 123 | K10: 67763285 | L10: =+VLOOKUP(A10,Hoja2!$A$2:$X$2596,19,FALSE) -> #N/A | M10: =+VLOOKUP(A10,Hoja2!$A$2:$X$2596,15,FALSE) -> #N/A | N10: =+VLOOKUP(A10,Hoja2!$A$2:$X$2596,17,FALSE) -> #N/A | O10: =+VLOOKUP(A10,Hoja2!$A$2:$X$2596,22,FALSE) -> #N/A | P10: =+VLOOKUP(A10,Hoja2!$A$2:$X$2596,23,FALSE) -> #N/A | Q10: =+VLOOKUP(A10,Hoja2!$A$2:$X$2596,24,FALSE) -> #N/A
A11: 2073692 | B11: 83462 | C11: Desestimado | D11: 2 | E11: 1 | F11: 0 | G11: Calidad | H11: 44214.508 | I11: 44350.084 | J11: 136 | K11: 16380511 | L11: =+VLOOKUP(A11,Hoja2!$A$2:$X$2596,19,FALSE) -> En Ejecución | M11: =+VLOOKUP(A11,Hoja2!$A$2:$X$2596,15,FALSE) -> 21560455 | N11: =+VLOOKUP(A11,Hoja2!$A$2:$X$2596,17,FALSE) -> 1056645.9 | O11: =+VLOOKUP(A11,Hoja2!$A$2:$X$2596,22,FALSE) | P11: =+VLOOKUP(A11,Hoja2!$A$2:$X$2596,23,FALSE) | Q11: =+VLOOKUP(A11,Hoja2!$A$2:$X$2596,24,FALSE)
A12: 2073692 | B12: 83462 | C12: Desestimado | D12: 3 | E12: 3 | F12: 0 | G12: Calidad | H12: 44456.805 | I12: 44607.367 | J12: 151 | K12: 16380511 | L12: =+VLOOKUP(A12,Hoja2!$A$2:$X$2596,19,FALSE) -> En Ejecución | M12: =+VLOOKUP(A12,Hoja2!$A$2:$X$2596,15,FALSE) -> 21560455 | N12: =+VLOOKUP(A12,Hoja2!$A$2:$X$2596,17,FALSE) -> 1056645.9 | O12: =+VLOOKUP(A12,Hoja2!$A$2:$X$2596,22,FALSE) | P12: =+VLOOKUP(A12,Hoja2!$A$2:$X$2596,23,FALSE) | Q12: =+VLOOKUP(A12,Hoja2!$A$2:$X$2596,24,FALSE)
A13: 2073692 | B13: 83462 | C13: Aprobado | D13: 4 | E13: 4 | F13: 0 | G13: Calidad | H13: 44629.882 | I13: 44715.559 | J13: 86 | K13: 16380511 | L13: =+VLOOKUP(A13,Hoja2!$A$2:$X$2596,19,FALSE) -> En Ejecución | M13: =+VLOOKUP(A13,Hoja2!$A$2:$X$2596,15,FALSE) -> 21560455 | N13: =+VLOOKUP(A13,Hoja2!$A$2:$X$2596,17,FALSE) -> 1056645.9 | O13: =+VLOOKUP(A13,Hoja2!$A$2:$X$2596,22,FALSE) | P13: =+VLOOKUP(A13,Hoja2!$A$2:$X$2596,23,FALSE) | Q13: =+VLOOKUP(A13,Hoja2!$A$2:$X$2596,24,FALSE)
... A776: 2703585 | B776: 2703585 | C776: Observada | D776: 2 | E776: 0 | F776: 0 | G776: Admisibilidad | H776: 45936.464 | I776: 45950.451 | J776: 14 | K776: 1.2418542e+08 | L776: =+VLOOKUP(A776,Hoja2!$A$2:$X$2596,19,FALSE) -> #N/A | M776: =+VLOOKUP(A776,Hoja2!$A$2:$X$2596,15,FALSE) -> #N/A | N776: =+VLOOKUP(A776,Hoja2!$A$2:$X$2596,17,FALSE) -> #N/A | O776: =+VLOOKUP(A776,Hoja2!$A$2:$X$2596,22,FALSE) -> #N/A | P776: =+VLOOKUP(A776,Hoja2!$A$2:$X$2596,23,FALSE) -> #N/A | Q776: =+VLOOKUP(A776,Hoja2!$A$2:$X$2596,24,FALSE) -> #N/A

Sheet Hoja2
A1: 1 | B1: 2 | C1: 3 | D1: 4 | E1: 5 | F1: 6 | G1: 7 | H1: 8 | I1: 9 | J1: 10 | K1: 11 | L1: 12 | M1: 13 | N1: 14 | O1: 15 | P1: 16 | Q1: 17 | R1: 18 | S1: 19 | T1: 20 | U1: 21 | V1: 22 | W1: 23 | X1: 24
A2: CODIGO_UNIFICADO | B2: monto_snip | C2: id_proyecto | D2: subsector | E2: subprograma | F2: cod_snip | G2: monto_inversion | H2: CostoActual | I2: DevengadoAcumulado | J2: DevengadoTotal2019 | K2: PimTotal2019 | L2: estadoPIP | M2: Tipo | N2: MontoReferencial | O2: MontoContratado | P2: MontoReferencial2 | Q2: MontoContratado2 | R2: EstadoEjecucion | S2: Estado | T2: SubEstado | U2: SubEstado2 | V2: montoLiquidacion | W2: montoLiqSupervision | X2: montoLiqObraComplementaria
A3: 2015097 | B3: 80000 | C3: 31084 | D3: PNSU | E3: UNIDAD DE GESTION TERRITORIAL - UGT | F3: 33800 | G3: 80000 | H3: 80000 | I3: 0 | J3: 0 | K3: 0 | L3: DESACTIVADO PERMANENTE | M3: OBRA | R3: Concluido - En Liquidación | S3: Concluido | T3: En Liquidación | V3: 69467.85 | W3: 0 | X3: 0
A4: 2015662 | B4: 8456770 | C4: 31098 | D4: PNSU | E4: UNIDAD DE GESTION TERRITORIAL - UGT | F4: 5206 | G4: 8456770 | H4: 8456770 | I4: 570492.9 | J4: 0 | K4: 0 | L4: ACTIVO | M4: OBRA | R4: Concluido - Convenio Cerrado | S4: Concluido | T4: Convenio Cerrado | V4: 2707542.2 | W4: 0 | X4: 0
A5: 2017383 | B5: 20279145 | C5: 46823 | D5: PNSU | E5: UNIDAD DE GESTION TERRITORIAL - UGT | F5: 3101 | G5: 62312762 | H5: 1.1932883e+08 | I5: 87313828 | J5: 0 | K5: 66000 | L5: ACTIVO | M5: OBRA (SALDO) | N5: 49940958 | O5: 49940958 | P5: 731106 | Q5: 320201 | R5: Convenio y/o Contrato Resuelto | S5: Convenio y/o Contrato Resuelto
A6: 2017384 | B6: 141137863 | C6: 42121 | D6: PNSU | E6: UNIDAD DE PROYECTOS - AREA DE ESTUDIOS | F6: 3089 | G6: 141137863 | H6: 141137863 | I6: 639937.47 | J6: 0 | K6: 0 | L6: ACTIVO | M6: EXPEDIENTE TECNICO | R6: En elaboración - En Proceso | S6: En elaboración | T6: En Proceso
A7: 2018438 | B7: 1595256 | C7: 30947 | D7: PNSU | E7: UNIDAD DE GESTION TERRITORIAL - UGT | F7: 8727 | G7: 1595256 | H7: 1595256 | I7: 457956.79 | J7: 0 | K7: 0 | L7: CERRADO | M7: OBRA | N7: 1583190.6 | O7: 1330412.3 | R7: Concluido - En Liquidación | S7: Concluido | T7: En Liquidación | V7: 0 | W7: 0 | X7: 0
A8: 2018570 | B8: 1279390 | C8: 31284 | D8: PNSU | E8: UNIDAD DE GESTION TERRITORIAL - UGT | F8: 7331 | G8: 1279390 | H8: 1279390 | I8: 2320452.9 | J8: 0 | K8: 0 | L8: ACTIVO | M8: OBRA | R8: Concluido - Convenio Cerrado | S8: Concluido | T8: Convenio Cerrado | V8: 2004564.6 | W8: 0 | X8: 0
A9: 2022649 | B9: 26201116 | C9: 30952 | D9: PNSU | E9: UNIDAD DE GESTION TERRITORIAL - UGT | F9: 12762 | G9: 25234035 | H9: 25234035 | I9: 26804759 | J9: 0 | K9: 0 | L9: CERRADO | M9: OBRA | N9: 25294133 | O9: 25234035 | P9: 2022666.8 | Q9: 1869692 | R9: Concluido - En Liquidación | S9: Concluido | T9: En Liquidación | V9: 24818942 | W9: 0 | X9: 0
A10: 2023386 | B10: 371015 | C10: 30072 | D10: PNSU | E10: UNIDAD DE GESTION TERRITORIAL - UGT | F10: 22433 | G10: 371015 | H10: 371015 | I10: 9999.5 | J10: 0 | K10: 0 | L10: CERRADO | M10: OBRA | N10: 0 | O10: 4799112 | R10: Concluido - Convenio Cerrado | S10: Concluido | T10: Convenio Cerrado | V10: 0 | W10: 0 | X10: 0
A11: 2024436 | B11: 11213593 | C11: 30762 | D11: PNSU | E11: UNIDAD DE GESTION TERRITORIAL - UGT | F11: 19791 | G11: 13479302 | H11: 13479302 | I11: 16031168 | J11: 0 | K11: 0 | L11: ACTIVO | M11: OBRA | N11: 11213590 | O11: 10948312 | P11: 310000 | Q11: 300700 | R11: Concluido - Convenio Cerrado | S11: Concluido | T11: Convenio Cerrado | V11: 13642900 | W11: 483672.6 | X11: 0
A12: 2025625 | B12: 541396 | C12: 31053 | D12: PNSU | E12: UNIDAD DE GESTION TERRITORIAL - UGT | F12: 18175 | G12: 687791 | H12: 687791 | I12: 370898.6 | J12: 0 | K12: 0 | L12: ACTIVO | M12: OBRA | R12: Concluido - Convenio Cerrado | S12: Concluido | T12: Convenio Cerrado | V12: 329846.77 | W12: 0 | X12: 0
A13: 2025708 | B13: 10956790 | C13: 30384 | D13: PNSU | E13: UNIDAD DE GESTION TERRITORIAL - UGT | F13: 20077 | G13: 9230541.7 | H13: 6462115.3 | I13: 9230841.7 | J13: 0 | K13: 0 | L13: ACTIVO | M13: OBRA | N13: 6154397.9 | O13: 6462115.3 | P13: 173478.96 | Q13: 156131.07 | R13: Concluido - Recepción observada | S13: Concluido | T13: Recepción observada
A14: 2026794 | B14: 813093 | C14: 30496 | D14: PNSU | E14: UNIDAD DE GESTION TERRITORIAL - UGT | F14: 24381 | G14: 813093 | H14: 813093 | I14: 0 | J14: 0 | K14: 0 | L14: DESACTIVADO PERMANENTE | M14: OBRA | N14: 745887.05 | O14: 671298.35 | R14: Concluido - Convenio Cerrado | S14: Concluido | T14: Convenio Cerrado | V14: 691558.37 | W14: 0 | X14: 0
A15: 2027765 | B15: 2135621 | C15: 29856 | D15: PNSU | E15: UNIDAD DE GESTION TERRITORIAL - UGT | F15: 27692 | G15: 2135621 | H15: 2135621 | I15: 151790 | J15: 0 | K15: 0 | L15: CERRADO | M15: OBRA | N15: 1686585 | O15: 1838377.6 | P15: 68181.82 | Q15: 57000 | R15: Concluido - Convenio Cerrado | S15: Concluido | T15: Convenio Cerrado | V15: 963670.02 | W15: 58539 | X15: 0
A16: 2028330 | B16: 1016474 | C16: 31083 | D16: PNSU | E16: UNIDAD DE GESTION TERRITORIAL - UGT | F16: 15977 | G16: 1597845 | H16: 1597845 | I16: 1217914.6 | J16: 0 | K16: 0 | L16: CERRADO | M16: OBRA | R16: Concluido - Convenio Cerrado | S16: Concluido | T16: Convenio Cerrado | V16: 2137063.5 | W16: 7784.34 | X16: 0
A17: 2028948 | B17: 1409802 | C17: 31005 | D17: PNSU | E17: UNIDAD DE GESTION TERRITORIAL - UGT | F17: 7635 | G17: 1409802 | H17: 1409802 | I17: 0 | J17: 0 | K17: 0 | L17: DESACTIVADO PERMANENTE | M17: OBRA | R17: Concluido - Convenio Cerrado | S17: Concluido | T17: Convenio Cerrado | V17: 836881.67 | W17: 0 | X17: 0
A18: 2029016 | B18: 2807949 | C18: 31242 | D18: PNSU | E18: UNIDAD DE GESTION TERRITORIAL - UGT | F18: 27525 | G18: 4694693 | H18: 4694693 | I18: 5007805.8 | J18: 0 | K18: 0 | L18: CERRADO | M18: OBRA | R18: Concluido - Convenio Cerrado | S18: Concluido | T18: Convenio Cerrado | V18: 3697387.3 | W18: 0 | X18: 0
A19: 2030269 | B19: 1460854 | C19: 30147 | D19: PNSU | E19: UNIDAD DE GESTION TERRITORIAL - UGT | F19: 30412 | G19: 0 | M19: OBRA | N19: 1000428.7 | O19: 900385.87 | P19: 1000428.7 | Q19: 0 | R19: Concluido - Convenio Cerrado | S19: Concluido | T19: Convenio Cerrado | V19: 933523.55 | W19: 0 | X19: 0
A20: 2030270 | B20: 636540 | C20: 30149 | D20: PNSU | E20: UNIDAD DE GESTION TERRITORIAL - UGT | F20: 30431 | G20: 372895.39 | H20: 372895.39 | I20: 0 | J20: 0 | K20: 0 | L20: CERRADO | M20: OBRA | N20: 380081 | O20: 342073 | P20: 380081 | Q20: 0 | R20: Concluido - Convenio Cerrado | S20: Concluido | T20: Convenio Cerrado | V20: 254511.42 | W20: 0 | X20: 0
A21: 2030537 | B21: 8645797 | C21: 30638 | D21: PNSU | E21: UNIDAD DE GESTION TERRITORIAL - UGT | F21: 1872 | G21: 8645797 | H21: 8645797 | I21: 8539912.4 | J21: 0 | K21: 0 | L21: CERRADO | M21: OBRA | N21: 8645797 | O21: 9207680 | P21: 185254.44 | Q21: 155676 | R21: Concluido - Liquidada | S21: Concluido | T21: Liquidada | V21: 0 | W21: 155676 | X21: 0
A22: 2030538 | B22: 1993909 | C22: 30861 | D22: PNSU | E22: UNIDAD DE GESTION TERRITORIAL - UGT | F22: 12190 | G22: 4072124.3 | H22: 4072124.3 | I22: 4169239.9 | J22: 0 | K22: 0 | L22: CERRADO | M22: OBRA | N22: 1919020 | O22: 1919020 | P22: 60000 | Q22: 54000 | R22: Concluido - Convenio Cerrado | S22: Concluido | T22: Convenio Cerrado | V22: 3359260.9 | W22: 0 | X22: 0
A23: 2030555 | B23: 1805329 | C23: 30722 | D23: PNSU | E23: UNIDAD DE GESTION TERRITORIAL - UGT | F23: 26583 | G23: 1805329 | H23: 1805329 | I23: 0 | J23: 0 | K23: 0 | L23: DESACTIVADO PERMANENTE | M23: OBRA | N23: 1315486.8 | O23: 1183938.2 | P23: 42697 | Q23: 38427.3 | R23: Concluido - Convenio Cerrado | S23: Concluido | T23: Convenio Cerrado | V23: 1183938.2 | W23: 0 | X23: 0
A24: 2030556 | B24: 1691681 | C24: 30734 | D24: PNSU | E24: UNIDAD DE GESTION TERRITORIAL - UGT | F24: 26787 | G24: 1691681 | H24: 1691681 | I24: 1903517.8 | J24: 0 | K24: 0 | L24: CERRADO | M24: OBRA | N24: 1824351 | O24: 1824351 | P24: 36130.02 | Q24: 32517.02 | R24: Concluido - Convenio Cerrado | S24: Concluido | T24: Convenio Cerrado | V24: 1862667.6 | W24: 0 | X24: 0
A25: 2016436 | B25: 490932.29 | C25: 30685 | D25: PNSU | E25: UNIDAD DE GESTION TERRITORIAL - UGT | F25: 7672 | G25: 490932.29 | H25: 490932.29 | I25: 667964.28 | J25: 0 | K25: 0 | L25: ACTIVO | M25: OBRA | N25: 143713 | O25: 140839 | R25: Concluido - Convenio Cerrado | S25: Concluido | T25: Convenio Cerrado | V25: 148001.84 | W25: 0 | X25: 0
A26: 2017265 | B26: 1893011.8 | C26: 30694 | D26: PNSU | E26: UNIDAD DE GESTION TERRITORIAL - UGT | F26: 7008 | G26: 1893011.8 | H26: 1893011.8 | I26: 2197967.6 | J26: 0 | K26: 0 | L26: CERRADO | M26: OBRA | N26: 555904 | O26: 555904 | P26: 555904 | Q26: 13086.34 | R26: Concluido - Convenio Cerrado | S26: Concluido | T26: Convenio Cerrado | V26: 711029.89 | W26: 0 | X26: 0
A27: 2018910 | B27: 1486177 | C27: 30950 | D27: PNSU | E27: UNIDAD DE GESTION TERRITORIAL - UGT | F27: 11773 | G27: 1486177 | H27: 1486177 | I27: 2338064.4 | J27: 0 | K27: 0 | L27: CERRADO | M27: OBRA | N27: 2060703.9 | O27: 1645099.7 | R27: Concluido - En Liquidación | S27: Concluido | T27: En Liquidación | V27: 768349.68 | W27: 0 | X27: 2234300.5
A28: 2018978 | B28: 1970046 | C28: 31233 | D28: PNSU | E28: UNIDAD DE GESTION TERRITORIAL - UGT | F28: 4319 | G28: 1999586.3 | H28: 1999586.3 | I28: 2144524.7 | J28: 0 | K28: 0 | L28: CERRADO | M28: OBRA | R28: Concluido - En Liquidación | S28: Concluido | T28: En Liquidación | V28: 2136756.8 | W28: 0 | X28: 0
A29: 2019410 | B29: 843490 | C29: 29936 | D29: PNSU | E29: UNIDAD DE GESTION TERRITORIAL - UGT | F29: 17787 | G29: 843490 | H29: 843490 | I29: 0 | J29: 0 | K29: 0 | L29: DESACTIVADO PERMANENTE | M29: OBRA | N29: 888489 | O29: 888489 | P29: 888489 | Q29: 0 | R29: Concluido - Convenio Cerrado | S29: Concluido | T29: Convenio Cerrado | V29: 872881.74 | W29: 10000 | X29: 0
A30: 2019444 | B30: 1565422 | C30: 31024 | D30: PNSU | E30: UNIDAD DE GESTION TERRITORIAL - UGT | F30: 12973 | G30: 1565422 | H30: 1565422 | I30: 0 | J30: 0 | K30: 0 | L30: DESACTIVADO PERMANENTE | M30: OBRA | R30: Concluido - Convenio Cerrado | S30: Concluido | T30: Convenio Cerrado | V30: 1856225 | W30: 0 | X30: 0
A31: 2019446 | B31: 221954 | C31: 29961 | D31: PNSU | E31: UNIDAD DE GESTION TERRITORIAL - UGT | F31: 12837 | G31: 1518234 | H31: 1574440.1 | I31: 1625796.7 | J31: 0 | K31: 0 | L31: ACTIVO | M31: OBRA | N31: 1486755.2 | O31: 1486755.2 | P31: 1486755.2 | Q31: 37168.89 | R31: Concluido - Convenio Cerrado | S31: Concluido | T31: Convenio Cerrado | V31: 1549609.9 | W31: 0 | X31: 0
A32: 2021584 | B32: 1999513 | C32: 31162 | D32: PNSU | E32: UNIDAD DE GESTION TERRITORIAL - UGT | F32: 18122 | G32: 1999513 | H32: 1999513 | I32: 1637768.9 | J32: 0 | K32: 0 | L32: CERRADO | M32: OBRA | R32: Concluido - Liquidada | S32: Concluido | T32: Liquidada | V32: 616052.82 | W32: 0 | X32: 0
A33: 2021877 | B33: 6804821 | C33: 30755 | D33: PNSU | E33: UNIDAD DE GESTION TERRITORIAL - UGT | F33: 702 | G33: 6804821 | H33: 6804821 | I33: 9497902.3 | J33: 0 | K33: 0 | L33: CERRADO | M33: OBRA | N33: 6622142 | O33: 7304641 | P33: 320809.13 | Q33: 288728.22 | R33: Concluido - Convenio Cerrado | S33: Concluido | T33: Convenio Cerrado | V33: 7447670.8 | W33: 0 | X33: 0
A34: 2022711 | B34: 3546394 | C34: 31063 | D34: PNSU | E34: UNIDAD DE GESTION TERRITORIAL - UGT | F34: 6336 | G34: 2899585 | H34: 2899585 | I34: 0 | J34: 0 | K34: 0 | L34: DESACTIVADO PERMANENTE | M34: OBRA | R34: Concluido - Convenio Cerrado | S34: Concluido | T34: Convenio Cerrado | V34: 2847100 | W34: 0 | X34: 0
A35: 2022722 | B35: 18278862 | C35: 48297 | D35: PNSU | E35: UNIDAD DE GESTION TERRITORIAL - UGT | F35: 9311 | G35: 42888139 | H35: 43126732 | I35: 14201456 | J35: 121768.69 | K35: 377880 | L35: ACTIVO | M35: OBRA (Expediente Saldo) | R35: En elaboración - En Proceso | S35: En elaboración | T35: En Proceso
A36: 2022945 | B36: 7429337 | C36: 30760 | D36: PNSU | E36: UNIDAD DE GESTION TERRITORIAL - UGT | F36: 9992 | G36: 9814397.7 | H36: 9814397.7 | I36: 9574525.4 | J36: 0 | K36: 0 | L36: CERRADO | M36: OBRA | N36: 7032213 | O36: 7383824 | P36: 397124 | Q36: 397124 | R36: Concluido - Liquidada | S36: Concluido | T36: Liquidada | V36: 8286721 | W36: 491835.37 | X36: 0
A37: 2025630 | B37: 870922 | C37: 30761 | D37: PNSU | E37: UNIDAD DE GESTION TERRITORIAL - UGT | F37: 19736 | G37: 870922 | H37: 870922 | I37: 2104123.4 | J37: 0 | K37: 0 | L37: CERRADO | M37: OBRA | N37: 1011471.4 | O37: 1222558.7 | R37: Concluido - Convenio Cerrado | S37: Concluido | T37: Convenio Cerrado | V37: 1222558.7 | W37: 0 | X37: 0
A38: 2025660 | B38: 1994896 | C38: 31081 | D38: PNSU | E38: UNIDAD DE GESTION TERRITORIAL - UGT | F38: 21765 | G38: 1994896 | H38: 1994896 | I38: 1375338.1 | J38: 0 | K38: 0 | L38: ACTIVO | M38: OBRA | R38: Concluido - En Liquidación | S38: Concluido | T38: En Liquidación | V38: 1897011.5 | W38: 95000 | X38: 0
A39: 2026355 | B39: 687022 | C39: 30819 | D39: PNSU | E39: UNIDAD DE GESTION TERRITORIAL - UGT | F39: 20292 | G39: 687022 | H39: 687022 | I39: 678412 | J39: 0 | K39: 0 | L39: CERRADO | M39: OBRA | N39: 666412 | O39: 666412 | P39: 0 | Q39: 12000 | R39: Concluido - En Liquidación | S39: Concluido | T39: En Liquidación | V39: 666411.99 | W39: 0 | X39: 0
A40: 2027825 | B40: 1067190 | C40: 30632 | D40: PNSU | E40: UNIDAD DE GESTION TERRITORIAL - UGT | F40: 25559 | G40: 1067190 | H40: 1067190 | I40: 611037.05 | J40: 0 | K40: 0 | L40: ACTIVO | M40: OBRA | N40: 891114.94 | O40: 673952.48 | P40: 20682.2 | Q40: 15642 | R40: Concluido - Liquidada | S40: Concluido | T40: Liquidada | V40: 777642.14 | W40: 0 | X40: 0
...
